[2024-02-21T22:25:48.721+0000] {taskinstance.py:1083} INFO - Dependencies all met for <TaskInstance: branchtest.branch_task manual__2024-02-21T22:25:46.912582+00:00 [queued]>
[2024-02-21T22:25:48.726+0000] {taskinstance.py:1083} INFO - Dependencies all met for <TaskInstance: branchtest.branch_task manual__2024-02-21T22:25:46.912582+00:00 [queued]>
[2024-02-21T22:25:48.726+0000] {taskinstance.py:1279} INFO - 
--------------------------------------------------------------------------------
[2024-02-21T22:25:48.726+0000] {taskinstance.py:1280} INFO - Starting attempt 1 of 1
[2024-02-21T22:25:48.726+0000] {taskinstance.py:1281} INFO - 
--------------------------------------------------------------------------------
[2024-02-21T22:25:48.734+0000] {taskinstance.py:1300} INFO - Executing <Task(BranchPythonOperator): branch_task> on 2024-02-21 22:25:46.912582+00:00
[2024-02-21T22:25:48.737+0000] {standard_task_runner.py:55} INFO - Started process 170 to run task
[2024-02-21T22:25:48.738+0000] {standard_task_runner.py:82} INFO - Running: ['***', 'tasks', 'run', 'branchtest', 'branch_task', 'manual__2024-02-21T22:25:46.912582+00:00', '--job-id', '54', '--raw', '--subdir', 'DAGS_FOLDER/branchs.py', '--cfg-path', '/tmp/tmpw0jlkx7x']
[2024-02-21T22:25:48.739+0000] {standard_task_runner.py:83} INFO - Job 54: Subtask branch_task
[2024-02-21T22:25:48.770+0000] {task_command.py:388} INFO - Running <TaskInstance: branchtest.branch_task manual__2024-02-21T22:25:46.912582+00:00 [running]> on host 4c825bec5701
[2024-02-21T22:25:48.806+0000] {taskinstance.py:1509} INFO - Exporting the following env vars:
AIRFLOW_CTX_DAG_OWNER=***
AIRFLOW_CTX_DAG_ID=branchtest
AIRFLOW_CTX_TASK_ID=branch_task
AIRFLOW_CTX_EXECUTION_DATE=2024-02-21T22:25:46.912582+00:00
AIRFLOW_CTX_TRY_NUMBER=1
AIRFLOW_CTX_DAG_RUN_ID=manual__2024-02-21T22:25:46.912582+00:00
[2024-02-21T22:25:48.807+0000] {taskinstance.py:1768} ERROR - Task failed with exception
Traceback (most recent call last):
  File "/home/airflow/.local/lib/python3.7/site-packages/airflow/operators/python.py", line 210, in execute
    branch = super().execute(context)
  File "/home/airflow/.local/lib/python3.7/site-packages/airflow/operators/python.py", line 175, in execute
    return_value = self.execute_callable()
  File "/home/airflow/.local/lib/python3.7/site-packages/airflow/operators/python.py", line 192, in execute_callable
    return self.python_callable(*self.op_args, **self.op_kwargs)
  File "/opt/airflow/dags/branchs.py", line 22, in avalia_numero_aleatorio
    number = context['task_instance'].xcom_pull(task_id="gera_numero_aleatorio_task")
  File "/home/airflow/.local/lib/python3.7/site-packages/airflow/utils/session.py", line 75, in wrapper
    return func(*args, session=session, **kwargs)
TypeError: xcom_pull() got an unexpected keyword argument 'task_id'
[2024-02-21T22:25:48.812+0000] {taskinstance.py:1323} INFO - Marking task as FAILED. dag_id=branchtest, task_id=branch_task, execution_date=20240221T222546, start_date=20240221T222548, end_date=20240221T222548
[2024-02-21T22:25:48.821+0000] {standard_task_runner.py:105} ERROR - Failed to execute job 54 for task branch_task (xcom_pull() got an unexpected keyword argument 'task_id'; 170)
[2024-02-21T22:25:48.830+0000] {local_task_job.py:208} INFO - Task exited with return code 1
[2024-02-21T22:25:48.849+0000] {taskinstance.py:2578} INFO - 0 downstream tasks scheduled from follow-on schedule check
