[2024-03-02T16:14:58.347+0000] {taskinstance.py:1083} INFO - Dependencies all met for <TaskInstance: gera_dados_turbina.file_sensor_task manual__2024-03-02T16:14:55.925424+00:00 [queued]>
[2024-03-02T16:14:58.355+0000] {taskinstance.py:1083} INFO - Dependencies all met for <TaskInstance: gera_dados_turbina.file_sensor_task manual__2024-03-02T16:14:55.925424+00:00 [queued]>
[2024-03-02T16:14:58.355+0000] {taskinstance.py:1279} INFO - 
--------------------------------------------------------------------------------
[2024-03-02T16:14:58.355+0000] {taskinstance.py:1280} INFO - Starting attempt 1 of 1
[2024-03-02T16:14:58.355+0000] {taskinstance.py:1281} INFO - 
--------------------------------------------------------------------------------
[2024-03-02T16:14:58.368+0000] {taskinstance.py:1300} INFO - Executing <Task(FileSensor): file_sensor_task> on 2024-03-02 16:14:55.925424+00:00
[2024-03-02T16:14:58.373+0000] {standard_task_runner.py:55} INFO - Started process 172 to run task
[2024-03-02T16:14:58.383+0000] {standard_task_runner.py:82} INFO - Running: ['***', 'tasks', 'run', 'gera_dados_turbina', 'file_sensor_task', 'manual__2024-03-02T16:14:55.925424+00:00', '--job-id', '3206', '--raw', '--subdir', 'DAGS_FOLDER/pipeline.py', '--cfg-path', '/tmp/tmpfubr_oe_']
[2024-03-02T16:14:58.384+0000] {standard_task_runner.py:83} INFO - Job 3206: Subtask file_sensor_task
[2024-03-02T16:14:58.446+0000] {task_command.py:388} INFO - Running <TaskInstance: gera_dados_turbina.file_sensor_task manual__2024-03-02T16:14:55.925424+00:00 [running]> on host 875967b47df7
[2024-03-02T16:14:58.504+0000] {taskinstance.py:1509} INFO - Exporting the following env vars:
AIRFLOW_CTX_DAG_OWNER=***
AIRFLOW_CTX_DAG_ID=gera_dados_turbina
AIRFLOW_CTX_TASK_ID=file_sensor_task
AIRFLOW_CTX_EXECUTION_DATE=2024-03-02T16:14:55.925424+00:00
AIRFLOW_CTX_TRY_NUMBER=1
AIRFLOW_CTX_DAG_RUN_ID=manual__2024-03-02T16:14:55.925424+00:00
[2024-03-02T16:14:58.516+0000] {taskinstance.py:1768} ERROR - Task failed with exception
Traceback (most recent call last):
  File "/home/airflow/.local/lib/python3.7/site-packages/airflow/sensors/base.py", line 199, in execute
    poke_return = self.poke(context)
  File "/home/airflow/.local/lib/python3.7/site-packages/airflow/sensors/filesystem.py", line 61, in poke
    hook = FSHook(self.fs_conn_id)
  File "/home/airflow/.local/lib/python3.7/site-packages/airflow/hooks/filesystem.py", line 38, in __init__
    conn = self.get_connection(conn_id)
  File "/home/airflow/.local/lib/python3.7/site-packages/airflow/hooks/base.py", line 72, in get_connection
    conn = Connection.get_connection_from_secrets(conn_id)
  File "/home/airflow/.local/lib/python3.7/site-packages/airflow/models/connection.py", line 435, in get_connection_from_secrets
    raise AirflowNotFoundException(f"The conn_id `{conn_id}` isn't defined")
airflow.exceptions.AirflowNotFoundException: The conn_id `fs_default` isn't defined
[2024-03-02T16:14:58.519+0000] {taskinstance.py:1323} INFO - Marking task as FAILED. dag_id=gera_dados_turbina, task_id=file_sensor_task, execution_date=20240302T161455, start_date=20240302T161458, end_date=20240302T161458
[2024-03-02T16:14:58.527+0000] {standard_task_runner.py:105} ERROR - Failed to execute job 3206 for task file_sensor_task (The conn_id `fs_default` isn't defined; 172)
[2024-03-02T16:14:58.547+0000] {local_task_job.py:208} INFO - Task exited with return code 1
[2024-03-02T16:14:58.571+0000] {taskinstance.py:2578} INFO - 0 downstream tasks scheduled from follow-on schedule check
