[2024-03-04T14:07:46.268+0000] {taskinstance.py:1083} INFO - Dependencies all met for <TaskInstance: gera_dados_turbina.group_check_temp.check_temp_branc_task manual__2024-03-04T14:07:41.935082+00:00 [queued]>
[2024-03-04T14:07:46.273+0000] {taskinstance.py:1083} INFO - Dependencies all met for <TaskInstance: gera_dados_turbina.group_check_temp.check_temp_branc_task manual__2024-03-04T14:07:41.935082+00:00 [queued]>
[2024-03-04T14:07:46.273+0000] {taskinstance.py:1279} INFO - 
--------------------------------------------------------------------------------
[2024-03-04T14:07:46.273+0000] {taskinstance.py:1280} INFO - Starting attempt 1 of 1
[2024-03-04T14:07:46.274+0000] {taskinstance.py:1281} INFO - 
--------------------------------------------------------------------------------
[2024-03-04T14:07:46.282+0000] {taskinstance.py:1300} INFO - Executing <Task(BranchPythonOperator): group_check_temp.check_temp_branc_task> on 2024-03-04 14:07:41.935082+00:00
[2024-03-04T14:07:46.285+0000] {standard_task_runner.py:55} INFO - Started process 180 to run task
[2024-03-04T14:07:46.286+0000] {standard_task_runner.py:82} INFO - Running: ['***', 'tasks', 'run', 'gera_dados_turbina', 'group_check_temp.check_temp_branc_task', 'manual__2024-03-04T14:07:41.935082+00:00', '--job-id', '3281', '--raw', '--subdir', 'DAGS_FOLDER/pipeline.py', '--cfg-path', '/tmp/tmp_tybh0l1']
[2024-03-04T14:07:46.288+0000] {standard_task_runner.py:83} INFO - Job 3281: Subtask group_check_temp.check_temp_branc_task
[2024-03-04T14:07:46.322+0000] {task_command.py:388} INFO - Running <TaskInstance: gera_dados_turbina.group_check_temp.check_temp_branc_task manual__2024-03-04T14:07:41.935082+00:00 [running]> on host 6c7c2f1829ed
[2024-03-04T14:07:46.360+0000] {taskinstance.py:1509} INFO - Exporting the following env vars:
AIRFLOW_CTX_DAG_EMAIL=adrianolima095@gmail.com
AIRFLOW_CTX_DAG_OWNER=***
AIRFLOW_CTX_DAG_ID=gera_dados_turbina
AIRFLOW_CTX_TASK_ID=group_check_temp.check_temp_branc_task
AIRFLOW_CTX_EXECUTION_DATE=2024-03-04T14:07:41.935082+00:00
AIRFLOW_CTX_TRY_NUMBER=1
AIRFLOW_CTX_DAG_RUN_ID=manual__2024-03-04T14:07:41.935082+00:00
[2024-03-04T14:07:46.366+0000] {python.py:177} INFO - Done. Returned value was: group_check_temp.send_email_normal_task
[2024-03-04T14:07:46.366+0000] {python.py:211} INFO - Branch callable return group_check_temp.send_email_normal_task
[2024-03-04T14:07:46.366+0000] {skipmixin.py:155} INFO - Following branch group_check_temp.send_email_normal_task
[2024-03-04T14:07:46.370+0000] {taskinstance.py:1768} ERROR - Task failed with exception
Traceback (most recent call last):
  File "/home/airflow/.local/lib/python3.7/site-packages/airflow/operators/python.py", line 212, in execute
    self.skip_all_except(context["ti"], branch)
  File "/home/airflow/.local/lib/python3.7/site-packages/airflow/models/skipmixin.py", line 186, in skip_all_except
    "'branch_task_ids' must contain only valid task_ids. "
airflow.exceptions.AirflowException: 'branch_task_ids' must contain only valid task_ids. Invalid tasks found: {'group_check_temp.send_email_normal_task'}.
[2024-03-04T14:07:46.372+0000] {taskinstance.py:1323} INFO - Marking task as FAILED. dag_id=gera_dados_turbina, task_id=group_check_temp.check_temp_branc_task, execution_date=20240304T140741, start_date=20240304T140746, end_date=20240304T140746
[2024-03-04T14:07:46.382+0000] {warnings.py:110} WARNING - /home/***/.local/lib/python3.7/site-packages/***/utils/email.py:152: RemovedInAirflow3Warning: Fetching SMTP credentials from configuration variables will be deprecated in a future release. Please set credentials using a connection instead.
  send_mime_email(e_from=mail_from, e_to=recipients, mime_msg=msg, conn_id=conn_id, dryrun=dryrun)

[2024-03-04T14:07:46.382+0000] {email.py:268} INFO - Email alerting: attempt 1
[2024-03-04T14:07:46.405+0000] {email.py:268} INFO - Email alerting: attempt 1
[2024-03-04T14:07:46.407+0000] {taskinstance.py:1831} ERROR - Failed to send email to: ['adrianolima095@gmail.com']
Traceback (most recent call last):
  File "/home/airflow/.local/lib/python3.7/site-packages/airflow/models/taskinstance.py", line 1374, in _run_raw_task
    self._execute_task_with_callbacks(context, test_mode)
  File "/home/airflow/.local/lib/python3.7/site-packages/airflow/models/taskinstance.py", line 1520, in _execute_task_with_callbacks
    result = self._execute_task(context, task_orig)
  File "/home/airflow/.local/lib/python3.7/site-packages/airflow/models/taskinstance.py", line 1581, in _execute_task
    result = execute_callable(context=context)
  File "/home/airflow/.local/lib/python3.7/site-packages/airflow/operators/python.py", line 212, in execute
    self.skip_all_except(context["ti"], branch)
  File "/home/airflow/.local/lib/python3.7/site-packages/airflow/models/skipmixin.py", line 186, in skip_all_except
    "'branch_task_ids' must contain only valid task_ids. "
airflow.exceptions.AirflowException: 'branch_task_ids' must contain only valid task_ids. Invalid tasks found: {'group_check_temp.send_email_normal_task'}.

During handling of the above exception, another exception occurred:

Traceback (most recent call last):
  File "/home/airflow/.local/lib/python3.7/site-packages/airflow/models/taskinstance.py", line 2231, in email_alert
    send_email(task.email, subject, html_content)
  File "/home/airflow/.local/lib/python3.7/site-packages/airflow/utils/email.py", line 91, in send_email
    **kwargs,
  File "/home/airflow/.local/lib/python3.7/site-packages/airflow/utils/email.py", line 152, in send_email_smtp
    send_mime_email(e_from=mail_from, e_to=recipients, mime_msg=msg, conn_id=conn_id, dryrun=dryrun)
  File "/home/airflow/.local/lib/python3.7/site-packages/airflow/utils/email.py", line 270, in send_mime_email
    smtp_conn = _get_smtp_connection(smtp_host, smtp_port, smtp_timeout, smtp_ssl)
  File "/home/airflow/.local/lib/python3.7/site-packages/airflow/utils/email.py", line 317, in _get_smtp_connection
    else smtplib.SMTP(host=host, port=port, timeout=timeout)
  File "/usr/local/lib/python3.7/smtplib.py", line 251, in __init__
    (code, msg) = self.connect(host, port)
  File "/usr/local/lib/python3.7/smtplib.py", line 336, in connect
    self.sock = self._get_socket(host, port, self.timeout)
  File "/usr/local/lib/python3.7/smtplib.py", line 307, in _get_socket
    self.source_address)
  File "/usr/local/lib/python3.7/socket.py", line 707, in create_connection
    for res in getaddrinfo(host, port, 0, SOCK_STREAM):
  File "/usr/local/lib/python3.7/socket.py", line 752, in getaddrinfo
    for res in _socket.getaddrinfo(host, port, family, type, proto, flags):
socket.gaierror: [Errno -2] Name or service not known

During handling of the above exception, another exception occurred:

Traceback (most recent call last):
  File "/home/airflow/.local/lib/python3.7/site-packages/airflow/models/taskinstance.py", line 1829, in handle_failure
    self.email_alert(error, task)
  File "/home/airflow/.local/lib/python3.7/site-packages/airflow/models/taskinstance.py", line 2233, in email_alert
    send_email(task.email, subject, html_content_err)
  File "/home/airflow/.local/lib/python3.7/site-packages/airflow/utils/email.py", line 91, in send_email
    **kwargs,
  File "/home/airflow/.local/lib/python3.7/site-packages/airflow/utils/email.py", line 152, in send_email_smtp
    send_mime_email(e_from=mail_from, e_to=recipients, mime_msg=msg, conn_id=conn_id, dryrun=dryrun)
  File "/home/airflow/.local/lib/python3.7/site-packages/airflow/utils/email.py", line 270, in send_mime_email
    smtp_conn = _get_smtp_connection(smtp_host, smtp_port, smtp_timeout, smtp_ssl)
  File "/home/airflow/.local/lib/python3.7/site-packages/airflow/utils/email.py", line 317, in _get_smtp_connection
    else smtplib.SMTP(host=host, port=port, timeout=timeout)
  File "/usr/local/lib/python3.7/smtplib.py", line 251, in __init__
    (code, msg) = self.connect(host, port)
  File "/usr/local/lib/python3.7/smtplib.py", line 336, in connect
    self.sock = self._get_socket(host, port, self.timeout)
  File "/usr/local/lib/python3.7/smtplib.py", line 307, in _get_socket
    self.source_address)
  File "/usr/local/lib/python3.7/socket.py", line 707, in create_connection
    for res in getaddrinfo(host, port, 0, SOCK_STREAM):
  File "/usr/local/lib/python3.7/socket.py", line 752, in getaddrinfo
    for res in _socket.getaddrinfo(host, port, family, type, proto, flags):
socket.gaierror: [Errno -2] Name or service not known
[2024-03-04T14:07:46.414+0000] {standard_task_runner.py:105} ERROR - Failed to execute job 3281 for task group_check_temp.check_temp_branc_task ('branch_task_ids' must contain only valid task_ids. Invalid tasks found: {'group_check_temp.send_email_normal_task'}.; 180)
[2024-03-04T14:07:46.458+0000] {local_task_job.py:208} INFO - Task exited with return code 1
[2024-03-04T14:07:46.477+0000] {taskinstance.py:2578} INFO - 0 downstream tasks scheduled from follow-on schedule check
