[2024-02-29T21:37:28.916+0000] {taskinstance.py:1083} INFO - Dependencies all met for <TaskInstance: gera_dados_turbina.gera_dados_task manual__2024-02-29T21:37:27.722600+00:00 [queued]>
[2024-02-29T21:37:28.921+0000] {taskinstance.py:1083} INFO - Dependencies all met for <TaskInstance: gera_dados_turbina.gera_dados_task manual__2024-02-29T21:37:27.722600+00:00 [queued]>
[2024-02-29T21:37:28.921+0000] {taskinstance.py:1279} INFO - 
--------------------------------------------------------------------------------
[2024-02-29T21:37:28.921+0000] {taskinstance.py:1280} INFO - Starting attempt 1 of 1
[2024-02-29T21:37:28.921+0000] {taskinstance.py:1281} INFO - 
--------------------------------------------------------------------------------
[2024-02-29T21:37:28.930+0000] {taskinstance.py:1300} INFO - Executing <Task(PythonOperator): gera_dados_task> on 2024-02-29 21:37:27.722600+00:00
[2024-02-29T21:37:28.934+0000] {standard_task_runner.py:55} INFO - Started process 525 to run task
[2024-02-29T21:37:28.936+0000] {standard_task_runner.py:82} INFO - Running: ['***', 'tasks', 'run', 'gera_dados_turbina', 'gera_dados_task', 'manual__2024-02-29T21:37:27.722600+00:00', '--job-id', '3166', '--raw', '--subdir', 'DAGS_FOLDER/pipeline.py', '--cfg-path', '/tmp/tmp5526lssh']
[2024-02-29T21:37:28.937+0000] {standard_task_runner.py:83} INFO - Job 3166: Subtask gera_dados_task
[2024-02-29T21:37:28.973+0000] {task_command.py:388} INFO - Running <TaskInstance: gera_dados_turbina.gera_dados_task manual__2024-02-29T21:37:27.722600+00:00 [running]> on host 134f1bd43d2a
[2024-02-29T21:37:29.016+0000] {taskinstance.py:1509} INFO - Exporting the following env vars:
AIRFLOW_CTX_DAG_OWNER=***
AIRFLOW_CTX_DAG_ID=gera_dados_turbina
AIRFLOW_CTX_TASK_ID=gera_dados_task
AIRFLOW_CTX_EXECUTION_DATE=2024-02-29T21:37:27.722600+00:00
AIRFLOW_CTX_TRY_NUMBER=1
AIRFLOW_CTX_DAG_RUN_ID=manual__2024-02-29T21:37:27.722600+00:00
[2024-02-29T21:37:29.017+0000] {taskinstance.py:1768} ERROR - Task failed with exception
Traceback (most recent call last):
  File "/home/airflow/.local/lib/python3.7/site-packages/airflow/operators/python.py", line 175, in execute
    return_value = self.execute_callable()
  File "/home/airflow/.local/lib/python3.7/site-packages/airflow/operators/python.py", line 192, in execute_callable
    return self.python_callable(*self.op_args, **self.op_kwargs)
  File "/opt/airflow/dags/pipeline.py", line 60, in gera_dados
    time.sleep(5000) # Espera 5 minuto antes de gerar o pr√≥ximo registro
AttributeError: type object 'datetime.time' has no attribute 'sleep'
[2024-02-29T21:37:29.021+0000] {taskinstance.py:1323} INFO - Marking task as FAILED. dag_id=gera_dados_turbina, task_id=gera_dados_task, execution_date=20240229T213727, start_date=20240229T213728, end_date=20240229T213729
[2024-02-29T21:37:29.028+0000] {standard_task_runner.py:105} ERROR - Failed to execute job 3166 for task gera_dados_task (type object 'datetime.time' has no attribute 'sleep'; 525)
[2024-02-29T21:37:29.068+0000] {local_task_job.py:208} INFO - Task exited with return code 1
[2024-02-29T21:37:29.079+0000] {taskinstance.py:2578} INFO - 0 downstream tasks scheduled from follow-on schedule check
