[2024-02-22T14:33:34.166+0000] {taskinstance.py:1083} INFO - Dependencies all met for <TaskInstance: pythonoperator.task1 manual__2024-02-22T14:33:33.052879+00:00 [queued]>
[2024-02-22T14:33:34.172+0000] {taskinstance.py:1083} INFO - Dependencies all met for <TaskInstance: pythonoperator.task1 manual__2024-02-22T14:33:33.052879+00:00 [queued]>
[2024-02-22T14:33:34.172+0000] {taskinstance.py:1279} INFO - 
--------------------------------------------------------------------------------
[2024-02-22T14:33:34.172+0000] {taskinstance.py:1280} INFO - Starting attempt 1 of 1
[2024-02-22T14:33:34.172+0000] {taskinstance.py:1281} INFO - 
--------------------------------------------------------------------------------
[2024-02-22T14:33:34.181+0000] {taskinstance.py:1300} INFO - Executing <Task(PythonOperator): task1> on 2024-02-22 14:33:33.052879+00:00
[2024-02-22T14:33:34.184+0000] {standard_task_runner.py:55} INFO - Started process 201 to run task
[2024-02-22T14:33:34.186+0000] {standard_task_runner.py:82} INFO - Running: ['***', 'tasks', 'run', 'pythonoperator', 'task1', 'manual__2024-02-22T14:33:33.052879+00:00', '--job-id', '91', '--raw', '--subdir', 'DAGS_FOLDER/pythonoperator.py', '--cfg-path', '/tmp/tmpuxzvw1_f']
[2024-02-22T14:33:34.187+0000] {standard_task_runner.py:83} INFO - Job 91: Subtask task1
[2024-02-22T14:33:34.224+0000] {task_command.py:388} INFO - Running <TaskInstance: pythonoperator.task1 manual__2024-02-22T14:33:33.052879+00:00 [running]> on host 0ec338b667ff
[2024-02-22T14:33:34.265+0000] {taskinstance.py:1509} INFO - Exporting the following env vars:
AIRFLOW_CTX_DAG_OWNER=***
AIRFLOW_CTX_DAG_ID=pythonoperator
AIRFLOW_CTX_TASK_ID=task1
AIRFLOW_CTX_EXECUTION_DATE=2024-02-22T14:33:33.052879+00:00
AIRFLOW_CTX_TRY_NUMBER=1
AIRFLOW_CTX_DAG_RUN_ID=manual__2024-02-22T14:33:33.052879+00:00
[2024-02-22T14:33:34.266+0000] {taskinstance.py:1768} ERROR - Task failed with exception
Traceback (most recent call last):
  File "/home/airflow/.local/lib/python3.7/site-packages/airflow/operators/python.py", line 175, in execute
    return_value = self.execute_callable()
  File "/home/airflow/.local/lib/python3.7/site-packages/airflow/operators/python.py", line 192, in execute_callable
    return self.python_callable(*self.op_args, **self.op_kwargs)
  File "/opt/airflow/dags/pythonoperator.py", line 16, in data_cleaner
    dataset = pd.read_csv("/data:/APP/data/Churn.csv", sep=";")
  File "/home/airflow/.local/lib/python3.7/site-packages/pandas/util/_decorators.py", line 311, in wrapper
    return func(*args, **kwargs)
  File "/home/airflow/.local/lib/python3.7/site-packages/pandas/io/parsers/readers.py", line 586, in read_csv
    return _read(filepath_or_buffer, kwds)
  File "/home/airflow/.local/lib/python3.7/site-packages/pandas/io/parsers/readers.py", line 482, in _read
    parser = TextFileReader(filepath_or_buffer, **kwds)
  File "/home/airflow/.local/lib/python3.7/site-packages/pandas/io/parsers/readers.py", line 811, in __init__
    self._engine = self._make_engine(self.engine)
  File "/home/airflow/.local/lib/python3.7/site-packages/pandas/io/parsers/readers.py", line 1040, in _make_engine
    return mapping[engine](self.f, **self.options)  # type: ignore[call-arg]
  File "/home/airflow/.local/lib/python3.7/site-packages/pandas/io/parsers/c_parser_wrapper.py", line 51, in __init__
    self._open_handles(src, kwds)
  File "/home/airflow/.local/lib/python3.7/site-packages/pandas/io/parsers/base_parser.py", line 229, in _open_handles
    errors=kwds.get("encoding_errors", "strict"),
  File "/home/airflow/.local/lib/python3.7/site-packages/pandas/io/common.py", line 707, in get_handle
    newline="",
FileNotFoundError: [Errno 2] No such file or directory: '/data:/APP/data/Churn.csv'
[2024-02-22T14:33:34.271+0000] {taskinstance.py:1323} INFO - Marking task as FAILED. dag_id=pythonoperator, task_id=task1, execution_date=20240222T143333, start_date=20240222T143334, end_date=20240222T143334
[2024-02-22T14:33:34.279+0000] {standard_task_runner.py:105} ERROR - Failed to execute job 91 for task task1 ([Errno 2] No such file or directory: '/data:/APP/data/Churn.csv'; 201)
[2024-02-22T14:33:34.317+0000] {local_task_job.py:208} INFO - Task exited with return code 1
[2024-02-22T14:33:34.328+0000] {taskinstance.py:2578} INFO - 0 downstream tasks scheduled from follow-on schedule check
