[2024-02-22T14:43:52.958+0000] {taskinstance.py:1083} INFO - Dependencies all met for <TaskInstance: pythonoperator.task1 manual__2024-02-22T14:43:52.030655+00:00 [queued]>
[2024-02-22T14:43:52.963+0000] {taskinstance.py:1083} INFO - Dependencies all met for <TaskInstance: pythonoperator.task1 manual__2024-02-22T14:43:52.030655+00:00 [queued]>
[2024-02-22T14:43:52.963+0000] {taskinstance.py:1279} INFO - 
--------------------------------------------------------------------------------
[2024-02-22T14:43:52.963+0000] {taskinstance.py:1280} INFO - Starting attempt 1 of 1
[2024-02-22T14:43:52.963+0000] {taskinstance.py:1281} INFO - 
--------------------------------------------------------------------------------
[2024-02-22T14:43:52.971+0000] {taskinstance.py:1300} INFO - Executing <Task(PythonOperator): task1> on 2024-02-22 14:43:52.030655+00:00
[2024-02-22T14:43:52.975+0000] {standard_task_runner.py:55} INFO - Started process 361 to run task
[2024-02-22T14:43:52.977+0000] {standard_task_runner.py:82} INFO - Running: ['***', 'tasks', 'run', 'pythonoperator', 'task1', 'manual__2024-02-22T14:43:52.030655+00:00', '--job-id', '102', '--raw', '--subdir', 'DAGS_FOLDER/pythonoperator.py', '--cfg-path', '/tmp/tmp687ehvz2']
[2024-02-22T14:43:52.978+0000] {standard_task_runner.py:83} INFO - Job 102: Subtask task1
[2024-02-22T14:43:53.010+0000] {task_command.py:388} INFO - Running <TaskInstance: pythonoperator.task1 manual__2024-02-22T14:43:52.030655+00:00 [running]> on host 369bc04fa622
[2024-02-22T14:43:53.047+0000] {taskinstance.py:1509} INFO - Exporting the following env vars:
AIRFLOW_CTX_DAG_OWNER=***
AIRFLOW_CTX_DAG_ID=pythonoperator
AIRFLOW_CTX_TASK_ID=task1
AIRFLOW_CTX_EXECUTION_DATE=2024-02-22T14:43:52.030655+00:00
AIRFLOW_CTX_TRY_NUMBER=1
AIRFLOW_CTX_DAG_RUN_ID=manual__2024-02-22T14:43:52.030655+00:00
[2024-02-22T14:43:53.052+0000] {taskinstance.py:1768} ERROR - Task failed with exception
Traceback (most recent call last):
  File "/home/airflow/.local/lib/python3.7/site-packages/pandas/core/indexes/base.py", line 3361, in get_loc
    return self._engine.get_loc(casted_key)
  File "pandas/_libs/index.pyx", line 76, in pandas._libs.index.IndexEngine.get_loc
  File "pandas/_libs/index.pyx", line 108, in pandas._libs.index.IndexEngine.get_loc
  File "pandas/_libs/hashtable_class_helper.pxi", line 5198, in pandas._libs.hashtable.PyObjectHashTable.get_item
  File "pandas/_libs/hashtable_class_helper.pxi", line 5206, in pandas._libs.hashtable.PyObjectHashTable.get_item
KeyError: 'genero'

The above exception was the direct cause of the following exception:

Traceback (most recent call last):
  File "/home/airflow/.local/lib/python3.7/site-packages/airflow/operators/python.py", line 175, in execute
    return_value = self.execute_callable()
  File "/home/airflow/.local/lib/python3.7/site-packages/airflow/operators/python.py", line 192, in execute_callable
    return self.python_callable(*self.op_args, **self.op_kwargs)
  File "/opt/airflow/dags/pythonoperator.py", line 22, in data_cleaner
    dataset['genero'].fillna('masculino', inplace=True) # Substitui valores null por masculino
  File "/home/airflow/.local/lib/python3.7/site-packages/pandas/core/frame.py", line 3458, in __getitem__
    indexer = self.columns.get_loc(key)
  File "/home/airflow/.local/lib/python3.7/site-packages/pandas/core/indexes/base.py", line 3363, in get_loc
    raise KeyError(key) from err
KeyError: 'genero'
[2024-02-22T14:43:53.057+0000] {taskinstance.py:1323} INFO - Marking task as FAILED. dag_id=pythonoperator, task_id=task1, execution_date=20240222T144352, start_date=20240222T144352, end_date=20240222T144353
[2024-02-22T14:43:53.064+0000] {standard_task_runner.py:105} ERROR - Failed to execute job 102 for task task1 ('genero'; 361)
[2024-02-22T14:43:53.069+0000] {local_task_job.py:208} INFO - Task exited with return code 1
[2024-02-22T14:43:53.078+0000] {taskinstance.py:2578} INFO - 0 downstream tasks scheduled from follow-on schedule check
