[2024-02-28T22:40:30.193+0000] {taskinstance.py:1083} INFO - Dependencies all met for <TaskInstance: gera_dados_turbina.gera_dados_task manual__2024-02-28T22:40:29.353586+00:00 [queued]>
[2024-02-28T22:40:30.199+0000] {taskinstance.py:1083} INFO - Dependencies all met for <TaskInstance: gera_dados_turbina.gera_dados_task manual__2024-02-28T22:40:29.353586+00:00 [queued]>
[2024-02-28T22:40:30.199+0000] {taskinstance.py:1279} INFO - 
--------------------------------------------------------------------------------
[2024-02-28T22:40:30.199+0000] {taskinstance.py:1280} INFO - Starting attempt 1 of 1
[2024-02-28T22:40:30.199+0000] {taskinstance.py:1281} INFO - 
--------------------------------------------------------------------------------
[2024-02-28T22:40:30.209+0000] {taskinstance.py:1300} INFO - Executing <Task(PythonOperator): gera_dados_task> on 2024-02-28 22:40:29.353586+00:00
[2024-02-28T22:40:30.214+0000] {standard_task_runner.py:55} INFO - Started process 137 to run task
[2024-02-28T22:40:30.216+0000] {standard_task_runner.py:82} INFO - Running: ['***', 'tasks', 'run', 'gera_dados_turbina', 'gera_dados_task', 'manual__2024-02-28T22:40:29.353586+00:00', '--job-id', '3146', '--raw', '--subdir', 'DAGS_FOLDER/gera_dados_turbina.py', '--cfg-path', '/tmp/tmpl4sxxbyf']
[2024-02-28T22:40:30.217+0000] {standard_task_runner.py:83} INFO - Job 3146: Subtask gera_dados_task
[2024-02-28T22:40:30.253+0000] {task_command.py:388} INFO - Running <TaskInstance: gera_dados_turbina.gera_dados_task manual__2024-02-28T22:40:29.353586+00:00 [running]> on host 8375a0c5e0f8
[2024-02-28T22:40:30.291+0000] {taskinstance.py:1509} INFO - Exporting the following env vars:
AIRFLOW_CTX_DAG_OWNER=***
AIRFLOW_CTX_DAG_ID=gera_dados_turbina
AIRFLOW_CTX_TASK_ID=gera_dados_task
AIRFLOW_CTX_EXECUTION_DATE=2024-02-28T22:40:29.353586+00:00
AIRFLOW_CTX_TRY_NUMBER=1
AIRFLOW_CTX_DAG_RUN_ID=manual__2024-02-28T22:40:29.353586+00:00
[2024-02-28T22:40:30.292+0000] {taskinstance.py:1768} ERROR - Task failed with exception
Traceback (most recent call last):
  File "/home/airflow/.local/lib/python3.7/site-packages/airflow/operators/python.py", line 175, in execute
    return_value = self.execute_callable()
  File "/home/airflow/.local/lib/python3.7/site-packages/airflow/operators/python.py", line 192, in execute_callable
    return self.python_callable(*self.op_args, **self.op_kwargs)
  File "/opt/airflow/dags/gera_dados_turbina.py", line 47, in gera_dados
    with open('/home/adriano/ed/APP/data/data_turbine.json', 'w') as fp:
FileNotFoundError: [Errno 2] No such file or directory: '/home/adriano/ed/APP/data/data_turbine.json'
[2024-02-28T22:40:30.296+0000] {taskinstance.py:1323} INFO - Marking task as FAILED. dag_id=gera_dados_turbina, task_id=gera_dados_task, execution_date=20240228T224029, start_date=20240228T224030, end_date=20240228T224030
[2024-02-28T22:40:30.303+0000] {standard_task_runner.py:105} ERROR - Failed to execute job 3146 for task gera_dados_task ([Errno 2] No such file or directory: '/home/adriano/ed/APP/data/data_turbine.json'; 137)
[2024-02-28T22:40:30.307+0000] {local_task_job.py:208} INFO - Task exited with return code 1
[2024-02-28T22:40:30.317+0000] {taskinstance.py:2578} INFO - 0 downstream tasks scheduled from follow-on schedule check
