[2024-03-04T12:40:20.411+0000] {taskinstance.py:1083} INFO - Dependencies all met for <TaskInstance: gera_dados_turbina.file_sensor_task manual__2024-03-04T12:40:17.679276+00:00 [queued]>
[2024-03-04T12:40:20.416+0000] {taskinstance.py:1083} INFO - Dependencies all met for <TaskInstance: gera_dados_turbina.file_sensor_task manual__2024-03-04T12:40:17.679276+00:00 [queued]>
[2024-03-04T12:40:20.417+0000] {taskinstance.py:1279} INFO - 
--------------------------------------------------------------------------------
[2024-03-04T12:40:20.417+0000] {taskinstance.py:1280} INFO - Starting attempt 1 of 1
[2024-03-04T12:40:20.417+0000] {taskinstance.py:1281} INFO - 
--------------------------------------------------------------------------------
[2024-03-04T12:40:20.424+0000] {taskinstance.py:1300} INFO - Executing <Task(FileSensor): file_sensor_task> on 2024-03-04 12:40:17.679276+00:00
[2024-03-04T12:40:20.428+0000] {standard_task_runner.py:55} INFO - Started process 172 to run task
[2024-03-04T12:40:20.429+0000] {standard_task_runner.py:82} INFO - Running: ['***', 'tasks', 'run', 'gera_dados_turbina', 'file_sensor_task', 'manual__2024-03-04T12:40:17.679276+00:00', '--job-id', '3228', '--raw', '--subdir', 'DAGS_FOLDER/pipeline.py', '--cfg-path', '/tmp/tmphwsby1_c']
[2024-03-04T12:40:20.430+0000] {standard_task_runner.py:83} INFO - Job 3228: Subtask file_sensor_task
[2024-03-04T12:40:20.462+0000] {task_command.py:388} INFO - Running <TaskInstance: gera_dados_turbina.file_sensor_task manual__2024-03-04T12:40:17.679276+00:00 [running]> on host 6d7d00f325e8
[2024-03-04T12:40:20.500+0000] {taskinstance.py:1509} INFO - Exporting the following env vars:
AIRFLOW_CTX_DAG_EMAIL=adrianolima095@gmail.com
AIRFLOW_CTX_DAG_OWNER=***
AIRFLOW_CTX_DAG_ID=gera_dados_turbina
AIRFLOW_CTX_TASK_ID=file_sensor_task
AIRFLOW_CTX_EXECUTION_DATE=2024-03-04T12:40:17.679276+00:00
AIRFLOW_CTX_TRY_NUMBER=1
AIRFLOW_CTX_DAG_RUN_ID=manual__2024-03-04T12:40:17.679276+00:00
[2024-03-04T12:40:20.509+0000] {taskinstance.py:1768} ERROR - Task failed with exception
Traceback (most recent call last):
  File "/home/airflow/.local/lib/python3.7/site-packages/airflow/sensors/base.py", line 199, in execute
    poke_return = self.poke(context)
  File "/home/airflow/.local/lib/python3.7/site-packages/airflow/sensors/filesystem.py", line 61, in poke
    hook = FSHook(self.fs_conn_id)
  File "/home/airflow/.local/lib/python3.7/site-packages/airflow/hooks/filesystem.py", line 38, in __init__
    conn = self.get_connection(conn_id)
  File "/home/airflow/.local/lib/python3.7/site-packages/airflow/hooks/base.py", line 72, in get_connection
    conn = Connection.get_connection_from_secrets(conn_id)
  File "/home/airflow/.local/lib/python3.7/site-packages/airflow/models/connection.py", line 435, in get_connection_from_secrets
    raise AirflowNotFoundException(f"The conn_id `{conn_id}` isn't defined")
airflow.exceptions.AirflowNotFoundException: The conn_id `fs_default` isn't defined
[2024-03-04T12:40:20.511+0000] {taskinstance.py:1323} INFO - Marking task as FAILED. dag_id=gera_dados_turbina, task_id=file_sensor_task, execution_date=20240304T124017, start_date=20240304T124020, end_date=20240304T124020
[2024-03-04T12:40:20.518+0000] {warnings.py:110} WARNING - /home/***/.local/lib/python3.7/site-packages/***/utils/email.py:152: RemovedInAirflow3Warning: Fetching SMTP credentials from configuration variables will be deprecated in a future release. Please set credentials using a connection instead.
  send_mime_email(e_from=mail_from, e_to=recipients, mime_msg=msg, conn_id=conn_id, dryrun=dryrun)

[2024-03-04T12:40:20.518+0000] {email.py:268} INFO - Email alerting: attempt 1
[2024-03-04T12:40:20.772+0000] {email.py:268} INFO - Email alerting: attempt 1
[2024-03-04T12:40:20.775+0000] {taskinstance.py:1831} ERROR - Failed to send email to: ['adrianolima095@gmail.com']
Traceback (most recent call last):
  File "/home/airflow/.local/lib/python3.7/site-packages/airflow/models/taskinstance.py", line 1374, in _run_raw_task
    self._execute_task_with_callbacks(context, test_mode)
  File "/home/airflow/.local/lib/python3.7/site-packages/airflow/models/taskinstance.py", line 1520, in _execute_task_with_callbacks
    result = self._execute_task(context, task_orig)
  File "/home/airflow/.local/lib/python3.7/site-packages/airflow/models/taskinstance.py", line 1581, in _execute_task
    result = execute_callable(context=context)
  File "/home/airflow/.local/lib/python3.7/site-packages/airflow/sensors/base.py", line 199, in execute
    poke_return = self.poke(context)
  File "/home/airflow/.local/lib/python3.7/site-packages/airflow/sensors/filesystem.py", line 61, in poke
    hook = FSHook(self.fs_conn_id)
  File "/home/airflow/.local/lib/python3.7/site-packages/airflow/hooks/filesystem.py", line 38, in __init__
    conn = self.get_connection(conn_id)
  File "/home/airflow/.local/lib/python3.7/site-packages/airflow/hooks/base.py", line 72, in get_connection
    conn = Connection.get_connection_from_secrets(conn_id)
  File "/home/airflow/.local/lib/python3.7/site-packages/airflow/models/connection.py", line 435, in get_connection_from_secrets
    raise AirflowNotFoundException(f"The conn_id `{conn_id}` isn't defined")
airflow.exceptions.AirflowNotFoundException: The conn_id `fs_default` isn't defined

During handling of the above exception, another exception occurred:

Traceback (most recent call last):
  File "/home/airflow/.local/lib/python3.7/site-packages/airflow/models/taskinstance.py", line 2231, in email_alert
    send_email(task.email, subject, html_content)
  File "/home/airflow/.local/lib/python3.7/site-packages/airflow/utils/email.py", line 91, in send_email
    **kwargs,
  File "/home/airflow/.local/lib/python3.7/site-packages/airflow/utils/email.py", line 152, in send_email_smtp
    send_mime_email(e_from=mail_from, e_to=recipients, mime_msg=msg, conn_id=conn_id, dryrun=dryrun)
  File "/home/airflow/.local/lib/python3.7/site-packages/airflow/utils/email.py", line 270, in send_mime_email
    smtp_conn = _get_smtp_connection(smtp_host, smtp_port, smtp_timeout, smtp_ssl)
  File "/home/airflow/.local/lib/python3.7/site-packages/airflow/utils/email.py", line 317, in _get_smtp_connection
    else smtplib.SMTP(host=host, port=port, timeout=timeout)
  File "/usr/local/lib/python3.7/smtplib.py", line 251, in __init__
    (code, msg) = self.connect(host, port)
  File "/usr/local/lib/python3.7/smtplib.py", line 336, in connect
    self.sock = self._get_socket(host, port, self.timeout)
  File "/usr/local/lib/python3.7/smtplib.py", line 307, in _get_socket
    self.source_address)
  File "/usr/local/lib/python3.7/socket.py", line 707, in create_connection
    for res in getaddrinfo(host, port, 0, SOCK_STREAM):
  File "/usr/local/lib/python3.7/socket.py", line 752, in getaddrinfo
    for res in _socket.getaddrinfo(host, port, family, type, proto, flags):
socket.gaierror: [Errno -2] Name or service not known

During handling of the above exception, another exception occurred:

Traceback (most recent call last):
  File "/home/airflow/.local/lib/python3.7/site-packages/airflow/models/taskinstance.py", line 1829, in handle_failure
    self.email_alert(error, task)
  File "/home/airflow/.local/lib/python3.7/site-packages/airflow/models/taskinstance.py", line 2233, in email_alert
    send_email(task.email, subject, html_content_err)
  File "/home/airflow/.local/lib/python3.7/site-packages/airflow/utils/email.py", line 91, in send_email
    **kwargs,
  File "/home/airflow/.local/lib/python3.7/site-packages/airflow/utils/email.py", line 152, in send_email_smtp
    send_mime_email(e_from=mail_from, e_to=recipients, mime_msg=msg, conn_id=conn_id, dryrun=dryrun)
  File "/home/airflow/.local/lib/python3.7/site-packages/airflow/utils/email.py", line 270, in send_mime_email
    smtp_conn = _get_smtp_connection(smtp_host, smtp_port, smtp_timeout, smtp_ssl)
  File "/home/airflow/.local/lib/python3.7/site-packages/airflow/utils/email.py", line 317, in _get_smtp_connection
    else smtplib.SMTP(host=host, port=port, timeout=timeout)
  File "/usr/local/lib/python3.7/smtplib.py", line 251, in __init__
    (code, msg) = self.connect(host, port)
  File "/usr/local/lib/python3.7/smtplib.py", line 336, in connect
    self.sock = self._get_socket(host, port, self.timeout)
  File "/usr/local/lib/python3.7/smtplib.py", line 307, in _get_socket
    self.source_address)
  File "/usr/local/lib/python3.7/socket.py", line 707, in create_connection
    for res in getaddrinfo(host, port, 0, SOCK_STREAM):
  File "/usr/local/lib/python3.7/socket.py", line 752, in getaddrinfo
    for res in _socket.getaddrinfo(host, port, family, type, proto, flags):
socket.gaierror: [Errno -2] Name or service not known
[2024-03-04T12:40:20.784+0000] {standard_task_runner.py:105} ERROR - Failed to execute job 3228 for task file_sensor_task (The conn_id `fs_default` isn't defined; 172)
[2024-03-04T12:40:20.802+0000] {local_task_job.py:208} INFO - Task exited with return code 1
[2024-03-04T12:40:20.822+0000] {taskinstance.py:2578} INFO - 0 downstream tasks scheduled from follow-on schedule check
