[2024-02-29T22:59:23.738+0000] {taskinstance.py:1083} INFO - Dependencies all met for <TaskInstance: gera_dados_turbina.gera_dados_task manual__2024-02-29T22:59:22.619667+00:00 [queued]>
[2024-02-29T22:59:23.744+0000] {taskinstance.py:1083} INFO - Dependencies all met for <TaskInstance: gera_dados_turbina.gera_dados_task manual__2024-02-29T22:59:22.619667+00:00 [queued]>
[2024-02-29T22:59:23.744+0000] {taskinstance.py:1279} INFO - 
--------------------------------------------------------------------------------
[2024-02-29T22:59:23.744+0000] {taskinstance.py:1280} INFO - Starting attempt 1 of 1
[2024-02-29T22:59:23.744+0000] {taskinstance.py:1281} INFO - 
--------------------------------------------------------------------------------
[2024-02-29T22:59:23.752+0000] {taskinstance.py:1300} INFO - Executing <Task(PythonOperator): gera_dados_task> on 2024-02-29 22:59:22.619667+00:00
[2024-02-29T22:59:23.757+0000] {standard_task_runner.py:55} INFO - Started process 169 to run task
[2024-02-29T22:59:23.759+0000] {standard_task_runner.py:82} INFO - Running: ['***', 'tasks', 'run', 'gera_dados_turbina', 'gera_dados_task', 'manual__2024-02-29T22:59:22.619667+00:00', '--job-id', '3176', '--raw', '--subdir', 'DAGS_FOLDER/pipeline.py', '--cfg-path', '/tmp/tmpcl5jg46v']
[2024-02-29T22:59:23.760+0000] {standard_task_runner.py:83} INFO - Job 3176: Subtask gera_dados_task
[2024-02-29T22:59:23.796+0000] {task_command.py:388} INFO - Running <TaskInstance: gera_dados_turbina.gera_dados_task manual__2024-02-29T22:59:22.619667+00:00 [running]> on host e2c8044673d4
[2024-02-29T22:59:23.835+0000] {taskinstance.py:1509} INFO - Exporting the following env vars:
AIRFLOW_CTX_DAG_OWNER=***
AIRFLOW_CTX_DAG_ID=gera_dados_turbina
AIRFLOW_CTX_TASK_ID=gera_dados_task
AIRFLOW_CTX_EXECUTION_DATE=2024-02-29T22:59:22.619667+00:00
AIRFLOW_CTX_TRY_NUMBER=1
AIRFLOW_CTX_DAG_RUN_ID=manual__2024-02-29T22:59:22.619667+00:00
[2024-02-29T22:59:23.836+0000] {taskinstance.py:1768} ERROR - Task failed with exception
Traceback (most recent call last):
  File "/home/airflow/.local/lib/python3.7/site-packages/airflow/operators/python.py", line 175, in execute
    return_value = self.execute_callable()
  File "/home/airflow/.local/lib/python3.7/site-packages/airflow/operators/python.py", line 192, in execute_callable
    return self.python_callable(*self.op_args, **self.op_kwargs)
  File "/opt/airflow/dags/pipeline.py", line 65, in gera_dados
    time.sleep(5000) # Espera 5 minuto antes de gerar o pr√≥ximo registro
AttributeError: type object 'datetime.time' has no attribute 'sleep'
[2024-02-29T22:59:23.840+0000] {taskinstance.py:1323} INFO - Marking task as FAILED. dag_id=gera_dados_turbina, task_id=gera_dados_task, execution_date=20240229T225922, start_date=20240229T225923, end_date=20240229T225923
[2024-02-29T22:59:23.847+0000] {standard_task_runner.py:105} ERROR - Failed to execute job 3176 for task gera_dados_task (type object 'datetime.time' has no attribute 'sleep'; 169)
[2024-02-29T22:59:23.891+0000] {local_task_job.py:208} INFO - Task exited with return code 1
[2024-02-29T22:59:23.902+0000] {taskinstance.py:2578} INFO - 0 downstream tasks scheduled from follow-on schedule check
