[2024-02-23T13:11:52.782+0000] {taskinstance.py:1083} INFO - Dependencies all met for <TaskInstance: bancodedados.print_result_task manual__2024-02-23T13:11:48.170729+00:00 [queued]>
[2024-02-23T13:11:52.787+0000] {taskinstance.py:1083} INFO - Dependencies all met for <TaskInstance: bancodedados.print_result_task manual__2024-02-23T13:11:48.170729+00:00 [queued]>
[2024-02-23T13:11:52.787+0000] {taskinstance.py:1279} INFO - 
--------------------------------------------------------------------------------
[2024-02-23T13:11:52.787+0000] {taskinstance.py:1280} INFO - Starting attempt 1 of 1
[2024-02-23T13:11:52.787+0000] {taskinstance.py:1281} INFO - 
--------------------------------------------------------------------------------
[2024-02-23T13:11:52.795+0000] {taskinstance.py:1300} INFO - Executing <Task(PythonOperator): print_result_task> on 2024-02-23 13:11:48.170729+00:00
[2024-02-23T13:11:52.798+0000] {standard_task_runner.py:55} INFO - Started process 174 to run task
[2024-02-23T13:11:52.799+0000] {standard_task_runner.py:82} INFO - Running: ['***', 'tasks', 'run', 'bancodedados', 'print_result_task', 'manual__2024-02-23T13:11:48.170729+00:00', '--job-id', '58', '--raw', '--subdir', 'DAGS_FOLDER/bancodedados.py', '--cfg-path', '/tmp/tmpg4km9a34']
[2024-02-23T13:11:52.800+0000] {standard_task_runner.py:83} INFO - Job 58: Subtask print_result_task
[2024-02-23T13:11:52.831+0000] {task_command.py:388} INFO - Running <TaskInstance: bancodedados.print_result_task manual__2024-02-23T13:11:48.170729+00:00 [running]> on host a03208ea8c06
[2024-02-23T13:11:52.867+0000] {taskinstance.py:1509} INFO - Exporting the following env vars:
AIRFLOW_CTX_DAG_OWNER=***
AIRFLOW_CTX_DAG_ID=bancodedados
AIRFLOW_CTX_TASK_ID=print_result_task
AIRFLOW_CTX_EXECUTION_DATE=2024-02-23T13:11:48.170729+00:00
AIRFLOW_CTX_TRY_NUMBER=1
AIRFLOW_CTX_DAG_RUN_ID=manual__2024-02-23T13:11:48.170729+00:00
[2024-02-23T13:11:52.867+0000] {taskinstance.py:1768} ERROR - Task failed with exception
Traceback (most recent call last):
  File "/home/airflow/.local/lib/python3.7/site-packages/airflow/operators/python.py", line 175, in execute
    return_value = self.execute_callable()
  File "/home/airflow/.local/lib/python3.7/site-packages/airflow/operators/python.py", line 192, in execute_callable
    return self.python_callable(*self.op_args, **self.op_kwargs)
  File "/opt/airflow/dags/bancodedados.py", line 14, in print_result
    task_instance = var.xcom_pull(task_ids='query_data')
AttributeError: 'dict' object has no attribute 'xcom_pull'
[2024-02-23T13:11:52.871+0000] {taskinstance.py:1323} INFO - Marking task as FAILED. dag_id=bancodedados, task_id=print_result_task, execution_date=20240223T131148, start_date=20240223T131152, end_date=20240223T131152
[2024-02-23T13:11:52.878+0000] {standard_task_runner.py:105} ERROR - Failed to execute job 58 for task print_result_task ('dict' object has no attribute 'xcom_pull'; 174)
[2024-02-23T13:11:52.891+0000] {local_task_job.py:208} INFO - Task exited with return code 1
[2024-02-23T13:11:52.901+0000] {taskinstance.py:2578} INFO - 0 downstream tasks scheduled from follow-on schedule check
