[2024-02-21T13:28:40.201+0000] {taskinstance.py:1083} INFO - Dependencies all met for <TaskInstance: variaveis.tsk1 manual__2024-02-21T13:28:39.858074+00:00 [queued]>
[2024-02-21T13:28:40.207+0000] {taskinstance.py:1083} INFO - Dependencies all met for <TaskInstance: variaveis.tsk1 manual__2024-02-21T13:28:39.858074+00:00 [queued]>
[2024-02-21T13:28:40.207+0000] {taskinstance.py:1279} INFO - 
--------------------------------------------------------------------------------
[2024-02-21T13:28:40.207+0000] {taskinstance.py:1280} INFO - Starting attempt 1 of 1
[2024-02-21T13:28:40.207+0000] {taskinstance.py:1281} INFO - 
--------------------------------------------------------------------------------
[2024-02-21T13:28:40.215+0000] {taskinstance.py:1300} INFO - Executing <Task(PythonOperator): tsk1> on 2024-02-21 13:28:39.858074+00:00
[2024-02-21T13:28:40.218+0000] {standard_task_runner.py:55} INFO - Started process 167 to run task
[2024-02-21T13:28:40.220+0000] {standard_task_runner.py:82} INFO - Running: ['***', 'tasks', 'run', 'variaveis', 'tsk1', 'manual__2024-02-21T13:28:39.858074+00:00', '--job-id', '21', '--raw', '--subdir', 'DAGS_FOLDER/variaveis.py', '--cfg-path', '/tmp/tmpmtv0i9ie']
[2024-02-21T13:28:40.220+0000] {standard_task_runner.py:83} INFO - Job 21: Subtask tsk1
[2024-02-21T13:28:40.253+0000] {task_command.py:388} INFO - Running <TaskInstance: variaveis.tsk1 manual__2024-02-21T13:28:39.858074+00:00 [running]> on host 9c95c3856b0c
[2024-02-21T13:28:40.293+0000] {taskinstance.py:1509} INFO - Exporting the following env vars:
AIRFLOW_CTX_DAG_OWNER=***
AIRFLOW_CTX_DAG_ID=variaveis
AIRFLOW_CTX_TASK_ID=tsk1
AIRFLOW_CTX_EXECUTION_DATE=2024-02-21T13:28:39.858074+00:00
AIRFLOW_CTX_TRY_NUMBER=1
AIRFLOW_CTX_DAG_RUN_ID=manual__2024-02-21T13:28:39.858074+00:00
[2024-02-21T13:28:40.297+0000] {taskinstance.py:1768} ERROR - Task failed with exception
Traceback (most recent call last):
  File "/home/airflow/.local/lib/python3.7/site-packages/airflow/operators/python.py", line 175, in execute
    return_value = self.execute_callable()
  File "/home/airflow/.local/lib/python3.7/site-packages/airflow/operators/python.py", line 192, in execute_callable
    return self.python_callable(*self.op_args, **self.op_kwargs)
  File "/opt/airflow/dags/variaveis.py", line 16, in print_variable
    print(f"O valor da variável é: {minhavar}")
NameError: name 'minhavar' is not defined
[2024-02-21T13:28:40.301+0000] {taskinstance.py:1323} INFO - Marking task as FAILED. dag_id=variaveis, task_id=tsk1, execution_date=20240221T132839, start_date=20240221T132840, end_date=20240221T132840
[2024-02-21T13:28:40.308+0000] {standard_task_runner.py:105} ERROR - Failed to execute job 21 for task tsk1 (name 'minhavar' is not defined; 167)
[2024-02-21T13:28:40.351+0000] {local_task_job.py:208} INFO - Task exited with return code 1
[2024-02-21T13:28:40.367+0000] {taskinstance.py:2578} INFO - 0 downstream tasks scheduled from follow-on schedule check
