[2024-02-29T19:21:41.942+0000] {taskinstance.py:1083} INFO - Dependencies all met for <TaskInstance: gera_dados_turbina.gera_dados_task manual__2024-02-29T19:21:40.218229+00:00 [queued]>
[2024-02-29T19:21:41.947+0000] {taskinstance.py:1083} INFO - Dependencies all met for <TaskInstance: gera_dados_turbina.gera_dados_task manual__2024-02-29T19:21:40.218229+00:00 [queued]>
[2024-02-29T19:21:41.947+0000] {taskinstance.py:1279} INFO - 
--------------------------------------------------------------------------------
[2024-02-29T19:21:41.947+0000] {taskinstance.py:1280} INFO - Starting attempt 1 of 1
[2024-02-29T19:21:41.947+0000] {taskinstance.py:1281} INFO - 
--------------------------------------------------------------------------------
[2024-02-29T19:21:41.955+0000] {taskinstance.py:1300} INFO - Executing <Task(PythonOperator): gera_dados_task> on 2024-02-29 19:21:40.218229+00:00
[2024-02-29T19:21:41.959+0000] {standard_task_runner.py:55} INFO - Started process 138 to run task
[2024-02-29T19:21:41.960+0000] {standard_task_runner.py:82} INFO - Running: ['***', 'tasks', 'run', 'gera_dados_turbina', 'gera_dados_task', 'manual__2024-02-29T19:21:40.218229+00:00', '--job-id', '3151', '--raw', '--subdir', 'DAGS_FOLDER/gera_dados_turbina.py', '--cfg-path', '/tmp/tmpr6cpygsn']
[2024-02-29T19:21:41.962+0000] {standard_task_runner.py:83} INFO - Job 3151: Subtask gera_dados_task
[2024-02-29T19:21:41.996+0000] {task_command.py:388} INFO - Running <TaskInstance: gera_dados_turbina.gera_dados_task manual__2024-02-29T19:21:40.218229+00:00 [running]> on host 835e03fd6c0e
[2024-02-29T19:21:42.036+0000] {taskinstance.py:1509} INFO - Exporting the following env vars:
AIRFLOW_CTX_DAG_OWNER=***
AIRFLOW_CTX_DAG_ID=gera_dados_turbina
AIRFLOW_CTX_TASK_ID=gera_dados_task
AIRFLOW_CTX_EXECUTION_DATE=2024-02-29T19:21:40.218229+00:00
AIRFLOW_CTX_TRY_NUMBER=1
AIRFLOW_CTX_DAG_RUN_ID=manual__2024-02-29T19:21:40.218229+00:00
[2024-02-29T19:21:42.036+0000] {taskinstance.py:1768} ERROR - Task failed with exception
Traceback (most recent call last):
  File "/home/airflow/.local/lib/python3.7/site-packages/airflow/operators/python.py", line 175, in execute
    return_value = self.execute_callable()
  File "/home/airflow/.local/lib/python3.7/site-packages/airflow/operators/python.py", line 192, in execute_callable
    return self.python_callable(*self.op_args, **self.op_kwargs)
  File "/opt/airflow/dags/gera_dados_turbina.py", line 47, in gera_dados
    with open('/home/adriano/ed/APP/data/data_turbine.json', 'w') as fp:
FileNotFoundError: [Errno 2] No such file or directory: '/home/adriano/ed/APP/data/data_turbine.json'
[2024-02-29T19:21:42.040+0000] {taskinstance.py:1323} INFO - Marking task as FAILED. dag_id=gera_dados_turbina, task_id=gera_dados_task, execution_date=20240229T192140, start_date=20240229T192141, end_date=20240229T192142
[2024-02-29T19:21:42.047+0000] {standard_task_runner.py:105} ERROR - Failed to execute job 3151 for task gera_dados_task ([Errno 2] No such file or directory: '/home/adriano/ed/APP/data/data_turbine.json'; 138)
[2024-02-29T19:21:42.052+0000] {local_task_job.py:208} INFO - Task exited with return code 1
[2024-02-29T19:21:42.062+0000] {taskinstance.py:2578} INFO - 0 downstream tasks scheduled from follow-on schedule check
