[2024-03-04T15:04:56.896+0000] {taskinstance.py:1083} INFO - Dependencies all met for <TaskInstance: gera_dados_turbina.group_check_temp.send_email_alert_task manual__2024-03-04T15:04:51.460208+00:00 [queued]>
[2024-03-04T15:04:56.902+0000] {taskinstance.py:1083} INFO - Dependencies all met for <TaskInstance: gera_dados_turbina.group_check_temp.send_email_alert_task manual__2024-03-04T15:04:51.460208+00:00 [queued]>
[2024-03-04T15:04:56.903+0000] {taskinstance.py:1279} INFO - 
--------------------------------------------------------------------------------
[2024-03-04T15:04:56.903+0000] {taskinstance.py:1280} INFO - Starting attempt 1 of 2
[2024-03-04T15:04:56.903+0000] {taskinstance.py:1281} INFO - 
--------------------------------------------------------------------------------
[2024-03-04T15:04:56.911+0000] {taskinstance.py:1300} INFO - Executing <Task(EmailOperator): group_check_temp.send_email_alert_task> on 2024-03-04 15:04:51.460208+00:00
[2024-03-04T15:04:56.914+0000] {standard_task_runner.py:55} INFO - Started process 196 to run task
[2024-03-04T15:04:56.916+0000] {standard_task_runner.py:82} INFO - Running: ['***', 'tasks', 'run', 'gera_dados_turbina', 'group_check_temp.send_email_alert_task', 'manual__2024-03-04T15:04:51.460208+00:00', '--job-id', '3336', '--raw', '--subdir', 'DAGS_FOLDER/pipeline.py', '--cfg-path', '/tmp/tmprf8walrg']
[2024-03-04T15:04:56.917+0000] {standard_task_runner.py:83} INFO - Job 3336: Subtask group_check_temp.send_email_alert_task
[2024-03-04T15:04:56.960+0000] {task_command.py:388} INFO - Running <TaskInstance: gera_dados_turbina.group_check_temp.send_email_alert_task manual__2024-03-04T15:04:51.460208+00:00 [running]> on host 61173039c7e2
[2024-03-04T15:04:57.056+0000] {taskinstance.py:1509} INFO - Exporting the following env vars:
AIRFLOW_CTX_DAG_EMAIL=adrianolima095@gmail.com
AIRFLOW_CTX_DAG_OWNER=***
AIRFLOW_CTX_DAG_ID=gera_dados_turbina
AIRFLOW_CTX_TASK_ID=group_check_temp.send_email_alert_task
AIRFLOW_CTX_EXECUTION_DATE=2024-03-04T15:04:51.460208+00:00
AIRFLOW_CTX_TRY_NUMBER=1
AIRFLOW_CTX_DAG_RUN_ID=manual__2024-03-04T15:04:51.460208+00:00
[2024-03-04T15:04:57.065+0000] {warnings.py:110} WARNING - /home/***/.local/lib/python3.7/site-packages/***/utils/email.py:152: RemovedInAirflow3Warning: Fetching SMTP credentials from configuration variables will be deprecated in a future release. Please set credentials using a connection instead.
  send_mime_email(e_from=mail_from, e_to=recipients, mime_msg=msg, conn_id=conn_id, dryrun=dryrun)

[2024-03-04T15:04:57.065+0000] {email.py:268} INFO - Email alerting: attempt 1
[2024-03-04T15:04:57.085+0000] {taskinstance.py:1768} ERROR - Task failed with exception
Traceback (most recent call last):
  File "/home/airflow/.local/lib/python3.7/site-packages/airflow/operators/email.py", line 87, in execute
    custom_headers=self.custom_headers,
  File "/home/airflow/.local/lib/python3.7/site-packages/airflow/utils/email.py", line 91, in send_email
    **kwargs,
  File "/home/airflow/.local/lib/python3.7/site-packages/airflow/utils/email.py", line 152, in send_email_smtp
    send_mime_email(e_from=mail_from, e_to=recipients, mime_msg=msg, conn_id=conn_id, dryrun=dryrun)
  File "/home/airflow/.local/lib/python3.7/site-packages/airflow/utils/email.py", line 270, in send_mime_email
    smtp_conn = _get_smtp_connection(smtp_host, smtp_port, smtp_timeout, smtp_ssl)
  File "/home/airflow/.local/lib/python3.7/site-packages/airflow/utils/email.py", line 317, in _get_smtp_connection
    else smtplib.SMTP(host=host, port=port, timeout=timeout)
  File "/usr/local/lib/python3.7/smtplib.py", line 251, in __init__
    (code, msg) = self.connect(host, port)
  File "/usr/local/lib/python3.7/smtplib.py", line 336, in connect
    self.sock = self._get_socket(host, port, self.timeout)
  File "/usr/local/lib/python3.7/smtplib.py", line 307, in _get_socket
    self.source_address)
  File "/usr/local/lib/python3.7/socket.py", line 707, in create_connection
    for res in getaddrinfo(host, port, 0, SOCK_STREAM):
  File "/usr/local/lib/python3.7/socket.py", line 752, in getaddrinfo
    for res in _socket.getaddrinfo(host, port, family, type, proto, flags):
socket.gaierror: [Errno -2] Name or service not known
[2024-03-04T15:04:57.092+0000] {taskinstance.py:1323} INFO - Marking task as UP_FOR_RETRY. dag_id=gera_dados_turbina, task_id=group_check_temp.send_email_alert_task, execution_date=20240304T150451, start_date=20240304T150456, end_date=20240304T150457
[2024-03-04T15:04:57.117+0000] {standard_task_runner.py:105} ERROR - Failed to execute job 3336 for task group_check_temp.send_email_alert_task ([Errno -2] Name or service not known; 196)
[2024-03-04T15:04:57.128+0000] {local_task_job.py:208} INFO - Task exited with return code 1
[2024-03-04T15:04:57.142+0000] {taskinstance.py:2578} INFO - 0 downstream tasks scheduled from follow-on schedule check
