[2024-02-23T13:56:39.282+0000] {taskinstance.py:1083} INFO - Dependencies all met for <TaskInstance: hooks.create_table_task manual__2024-02-23T13:56:38.589782+00:00 [queued]>
[2024-02-23T13:56:39.287+0000] {taskinstance.py:1083} INFO - Dependencies all met for <TaskInstance: hooks.create_table_task manual__2024-02-23T13:56:38.589782+00:00 [queued]>
[2024-02-23T13:56:39.288+0000] {taskinstance.py:1279} INFO - 
--------------------------------------------------------------------------------
[2024-02-23T13:56:39.288+0000] {taskinstance.py:1280} INFO - Starting attempt 1 of 1
[2024-02-23T13:56:39.288+0000] {taskinstance.py:1281} INFO - 
--------------------------------------------------------------------------------
[2024-02-23T13:56:39.295+0000] {taskinstance.py:1300} INFO - Executing <Task(PythonOperator): create_table_task> on 2024-02-23 13:56:38.589782+00:00
[2024-02-23T13:56:39.299+0000] {standard_task_runner.py:55} INFO - Started process 200 to run task
[2024-02-23T13:56:39.300+0000] {standard_task_runner.py:82} INFO - Running: ['***', 'tasks', 'run', 'hooks', 'create_table_task', 'manual__2024-02-23T13:56:38.589782+00:00', '--job-id', '71', '--raw', '--subdir', 'DAGS_FOLDER/hooks.py', '--cfg-path', '/tmp/tmp74_qv5pn']
[2024-02-23T13:56:39.301+0000] {standard_task_runner.py:83} INFO - Job 71: Subtask create_table_task
[2024-02-23T13:56:39.333+0000] {task_command.py:388} INFO - Running <TaskInstance: hooks.create_table_task manual__2024-02-23T13:56:38.589782+00:00 [running]> on host efd0032523b4
[2024-02-23T13:56:39.369+0000] {taskinstance.py:1509} INFO - Exporting the following env vars:
AIRFLOW_CTX_DAG_OWNER=***
AIRFLOW_CTX_DAG_ID=hooks
AIRFLOW_CTX_TASK_ID=create_table_task
AIRFLOW_CTX_EXECUTION_DATE=2024-02-23T13:56:38.589782+00:00
AIRFLOW_CTX_TRY_NUMBER=1
AIRFLOW_CTX_DAG_RUN_ID=manual__2024-02-23T13:56:38.589782+00:00
[2024-02-23T13:56:39.378+0000] {taskinstance.py:1768} ERROR - Task failed with exception
Traceback (most recent call last):
  File "/home/airflow/.local/lib/python3.7/site-packages/airflow/operators/python.py", line 175, in execute
    return_value = self.execute_callable()
  File "/home/airflow/.local/lib/python3.7/site-packages/airflow/operators/python.py", line 192, in execute_callable
    return self.python_callable(*self.op_args, **self.op_kwargs)
  File "/opt/airflow/dags/hooks.py", line 15, in create_table
    pg_hook.run("create table if not exists teste2(id int);", autocommit=True)
  File "/home/airflow/.local/lib/python3.7/site-packages/airflow/providers/common/sql/hooks/sql.py", line 342, in run
    with closing(self.get_conn()) as conn:
  File "/home/airflow/.local/lib/python3.7/site-packages/airflow/providers/postgres/hooks/postgres.py", line 117, in get_conn
    conn = deepcopy(self.connection or self.get_connection(conn_id))
  File "/home/airflow/.local/lib/python3.7/site-packages/airflow/hooks/base.py", line 72, in get_connection
    conn = Connection.get_connection_from_secrets(conn_id)
  File "/home/airflow/.local/lib/python3.7/site-packages/airflow/models/connection.py", line 435, in get_connection_from_secrets
    raise AirflowNotFoundException(f"The conn_id `{conn_id}` isn't defined")
airflow.exceptions.AirflowNotFoundException: The conn_id `postgres_default` isn't defined
[2024-02-23T13:56:39.380+0000] {taskinstance.py:1323} INFO - Marking task as FAILED. dag_id=hooks, task_id=create_table_task, execution_date=20240223T135638, start_date=20240223T135639, end_date=20240223T135639
[2024-02-23T13:56:39.387+0000] {standard_task_runner.py:105} ERROR - Failed to execute job 71 for task create_table_task (The conn_id `postgres_default` isn't defined; 200)
[2024-02-23T13:56:39.392+0000] {local_task_job.py:208} INFO - Task exited with return code 1
[2024-02-23T13:56:39.408+0000] {taskinstance.py:2578} INFO - 0 downstream tasks scheduled from follow-on schedule check
